<?xml version="1.0" encoding="utf-8" ?>
<!-- =================================================================================== -->
<!-- |    This document was autogenerated by xacro from /home/hayashi/worksp/tomato_ws/src/gazebo_ros_demos/rrbot_description/urdf/rrbot.xacro | -->
<!-- |    EDITING THIS FILE BY HAND IS NOT RECOMMENDED                                 | -->
<!-- =================================================================================== -->
<!-- Revolute-Revolute Manipulator -->
<robot name="rrbot" xmlns:xacro="http://www.ros.org/wiki/xacro">
    <!-- Link 7  EEF Link-->
    <!-- Link 6 -->
    <!-- Space btw top of beam and the each joint -->
    <!-- ros_control plugin -->
    <gazebo>
        <plugin filename="libgazebo_ros_control.so" name="gazebo_ros_control">
            <robotNamespace>/rrbot</robotNamespace>
            <robotSimType>gazebo_ros_control/DefaultRobotHWSim</robotSimType>
        </plugin>
    </gazebo>
    <!-- Link1 -->
    <gazebo reference="link1">
        <material>Gazebo/Orange</material>
    </gazebo>
    <!-- Link2 -->
    <gazebo reference="link2">
        <mu1>0.2</mu1>
        <mu2>0.2</mu2>
        <material>Gazebo/Black</material>
    </gazebo>
    <!-- Link3 -->
    <gazebo reference="link3">
        <mu1>0.2</mu1>
        <mu2>0.2</mu2>
        <material>Gazebo/Orange</material>
    </gazebo>
    <!-- camera_link -->
    <gazebo reference="camera_link">
        <mu1>0.2</mu1>
        <mu2>0.2</mu2>
        <material>Gazebo/Red</material>
    </gazebo>
    <!-- hokuyo -->
    <gazebo reference="hokuyo_link">
        <sensor name="head_hokuyo_sensor" type="gpu_ray">
            <pose>0 0 0 0 0 0</pose>
            <visualize>false</visualize>
            <update_rate>40</update_rate>
            <ray>
                <scan>
                    <horizontal>
                        <samples>720</samples>
                        <resolution>1</resolution>
                        <min_angle>-1.570796</min_angle>
                        <max_angle>1.570796</max_angle>
                    </horizontal>
                </scan>
                <range>
                    <min>0.10</min>
                    <max>30.0</max>
                    <resolution>0.01</resolution>
                </range>
                <noise>
                    <type>gaussian</type>
                    <!-- Noise parameters based on published spec for Hokuyo laser
               achieving "+-30mm" accuracy at range < 10m.  A mean of 0.0m and
               stddev of 0.01m will put 99.7% of samples within 0.03m of the true
               reading. -->
                    <mean>0.0</mean>
                    <stddev>0.01</stddev>
                </noise>
            </ray>
            <plugin filename="libgazebo_ros_gpu_laser.so" name="gazebo_ros_head_hokuyo_controller">
                <topicName>/rrbot/laser/scan</topicName>
                <frameName>hokuyo_link</frameName>
            </plugin>
        </sensor>
    </gazebo>
    <!-- camera -->
    <gazebo reference="camera_link">
        <sensor name="camera1" type="camera">
            <update_rate>30.0</update_rate>
            <camera name="head">
                <horizontal_fov>1.3962634</horizontal_fov>
                <image>
                    <width>800</width>
                    <height>800</height>
                    <format>R8G8B8</format>
                </image>
                <clip>
                    <near>0.02</near>
                    <far>300</far>
                </clip>
                <noise>
                    <type>gaussian</type>
                    <!-- Noise is sampled independently per pixel on each frame.
               That pixel's noise value is added to each of its color
               channels, which at that point lie in the range [0,1]. -->
                    <mean>0.0</mean>
                    <stddev>0.007</stddev>
                </noise>
            </camera>
            <plugin filename="libgazebo_ros_camera.so" name="camera_controller">
                <alwaysOn>true</alwaysOn>
                <updateRate>0.0</updateRate>
                <cameraName>rrbot/camera1</cameraName>
                <imageTopicName>image_raw</imageTopicName>
                <cameraInfoTopicName>camera_info</cameraInfoTopicName>
                <frameName>camera_link_optical</frameName>
                <!-- setting hackBaseline to anything but 0.0 will cause a misalignment
            between the gazebo sensor image and the frame it is supposed to
            be attached to -->
                <hackBaseline>0.0</hackBaseline>
                <distortionK1>0.0</distortionK1>
                <distortionK2>0.0</distortionK2>
                <distortionK3>0.0</distortionK3>
                <distortionT1>0.0</distortionT1>
                <distortionT2>0.0</distortionT2>
                <CxPrime>0</CxPrime>
                <Cx>0.0</Cx>
                <Cy>0.0</Cy>
                <focalLength>0.0</focalLength>
            </plugin>
        </sensor>
    </gazebo>
    <material name="black">
        <color rgba="0.0 0.0 0.0 1.0" />
    </material>
    <material name="blue">
        <color rgba="0.0 0.0 0.8 1.0" />
    </material>
    <material name="green">
        <color rgba="0.0 0.8 0.0 1.0" />
    </material>
    <material name="grey">
        <color rgba="0.2 0.2 0.2 1.0" />
    </material>
    <material name="orange">
        <color rgba="1.0 0.423529411765 0.0392156862745 1.0" />
    </material>
    <material name="brown">
        <color rgba="0.870588235294 0.811764705882 0.764705882353 1.0" />
    </material>
    <material name="red">
        <color rgba="0.8 0.0 0.0 1.0" />
    </material>
    <material name="white">
        <color rgba="1.0 1.0 1.0 1.0" />
    </material>
    <!-- Used for fixing robot to Gazebo 'base_link' -->
    <link name="world" />
    <joint name="fixed" type="fixed">
        <parent link="world" />
        <child link="link0" />
    </joint>
    <!-- Base Link -->
    <link name="link0">
        <collision>
            <origin rpy="0 0 0" xyz="0 0 0.13" />
            <geometry>
                <box size="0.05 0.05 0.26" />
            </geometry>
        </collision>
        <visual>
            <origin rpy="0 0 0" xyz="0 0 0.13" />
            <geometry>
                <box size="0.05 0.05 0.26" />
            </geometry>
            <material name="black" />
        </visual>
        
<inertial>
            <origin rpy="0 0 0" xyz="0 0 0.13" />
            <mass value="1" />
            <inertia ixx="0.00584166666667" ixy="0.0" ixz="0.0" iyy="0.00584166666667" iyz="0.0" izz="0.000416666666667" />
        </inertial>

    </link>
    <joint name="joint0" type="continuous">
        <parent link="link0" />
        <child link="link1" />
        <origin rpy="0 0 0" xyz="0 0 0.26" />
        <axis xyz="0 0 1" />
        <dynamics damping="0.0" />
    </joint>
    <!-- 1st Link -->
    <link name="link1">
        <collision>
            <origin rpy="0 0 0" xyz="0 0 0.0215" />
            <geometry>
                <box size="0.05 0.05 0.043" />
            </geometry>
        </collision>
        <visual>
            <origin rpy="0 0 0" xyz="0 0 0.0215" />
            <geometry>
                <box size="0.05 0.05 0.043" />
            </geometry>
            <material name="orange" />
        </visual>
        
<inertial>
            <origin rpy="0 0 0" xyz="0 0 0.0215" />
            <mass value="1" />
            <inertia ixx="0.000362416666667" ixy="0.0" ixz="0.0" iyy="0.000362416666667" iyz="0.0" izz="0.000416666666667" />
        </inertial>

    </link>
    <joint name="joint1" type="continuous">
        <parent link="link1" />
        <child link="link2" />
        <origin rpy="1.57079632679 0 0" xyz="0 0 0.043" />
        <axis xyz="0 0 1" />
        <dynamics damping="0.0" />
    </joint>
    <!-- 2nd Link -->
    <link name="link2">
        <collision>
            <origin rpy="1.57079632679 0 0" xyz="0 0.0525 0" />
            <geometry>
                <box size="0.05 0.05 0.105" />
            </geometry>
        </collision>
        <visual>
            <origin rpy="1.57079632679 0 0" xyz="0 0.0525 0" />
            <geometry>
                <box size="0.05 0.05 0.105" />
            </geometry>
            <material name="black" />
        </visual>
        
<inertial>
            <origin rpy="1.57079632679 0 0" xyz="0 0.0525 0" />
            <mass value="1" />
            <inertia ixx="0.00112708333333" ixy="0.0" ixz="0.0" iyy="0.00112708333333" iyz="0.0" izz="0.000416666666667" />
        </inertial>

    </link>
    <joint name="joint2" type="continuous">
        <parent link="link2" />
        <child link="link3" />
        <origin rpy="-1.57079632679 0 0" xyz="0 0.105 0" />
        <axis xyz="0 0 1" />
        <dynamics damping="0.0" />
    </joint>
    <!-- 3rd Link -->
    <link name="link3">
        <collision>
            <origin rpy="0 0 0" xyz="0 0 0.0215" />
            <geometry>
                <box size="0.05 0.05 0.043" />
            </geometry>
        </collision>
        <visual>
            <origin rpy="0 0 0" xyz="0 0 0.0215" />
            <geometry>
                <box size="0.05 0.05 0.043" />
            </geometry>
            <material name="orange" />
        </visual>
        
<inertial>
            <origin rpy="0 0 0" xyz="0 0 0.0215" />
            <mass value="1" />
            <inertia ixx="0.000362416666667" ixy="0.0" ixz="0.0" iyy="0.000362416666667" iyz="0.0" izz="0.000416666666667" />
        </inertial>

    </link>
    <joint name="joint3" type="continuous">
        <parent link="link3" />
        <child link="link4" />
        <origin rpy="1.57079632679 0 3.14159265359" xyz="0 0 0.043" />
        <axis xyz="0 0 1" />
        <dynamics damping="0.0" />
    </joint>
    <!-- 4th Link -->
    <link name="link4">
        <collision>
            <origin rpy="-1.57079632679 0 0" xyz="0 0.0205 0" />
            <geometry>
                <box size="0.05 0.05 0.041" />
            </geometry>
        </collision>
        <visual>
            <origin rpy="-1.57079632679 0 0" xyz="0 0.0205 0" />
            <geometry>
                <box size="0.05 0.05 0.041" />
            </geometry>
            <material name="black" />
        </visual>
        
<inertial>
            <origin rpy="-1.57079632679 0 0" xyz="0 0.0205 0" />
            <mass value="1" />
            <inertia ixx="0.000348416666667" ixy="0.0" ixz="0.0" iyy="0.000348416666667" iyz="0.0" izz="0.000416666666667" />
        </inertial>

    </link>
    <joint name="joint4" type="continuous">
        <parent link="link4" />
        <child link="link5" />
        <origin rpy="-1.57079632679 0 0" xyz="0 0.041 0" />
        <axis xyz="0 0 1" />
        <dynamics damping="0.0" />
    </joint>
    <!-- 5th Link -->
    <link name="link5">
        <collision>
            <origin rpy="0 0 0" xyz="0 0 0.055" />
            <geometry>
                <box size="0.05 0.05 0.11" />
            </geometry>
        </collision>
        <visual>
            <origin rpy="0 0 0" xyz="0 0 0.055" />
            <geometry>
                <box size="0.05 0.05 0.11" />
            </geometry>
            <material name="orange" />
        </visual>
        
<inertial>
            <origin rpy="0 0 0" xyz="0 0 0.055" />
            <mass value="1" />
            <inertia ixx="0.00121666666667" ixy="0.0" ixz="0.0" iyy="0.00121666666667" iyz="0.0" izz="0.000416666666667" />
        </inertial>

    </link>
    <joint name="joint5" type="continuous">
        <parent link="link5" />
        <child link="link6" />
        <origin rpy="1.57079632679 0 0" xyz="0 0 0.11" />
        <axis xyz="0 0 1" />
        <dynamics damping="0.0" />
    </joint>
    <!-- 6th Link -->
    <link name="link6">
        <collision>
            <origin rpy="-1.57079632679 0 0" xyz="0 0.0625 0" />
            <geometry>
                <box size="0.05 0.05 0.125" />
            </geometry>
        </collision>
        <visual>
            <origin rpy="-1.57079632679 0 0" xyz="0 0.0625 0" />
            <geometry>
                <box size="0.05 0.05 0.125" />
            </geometry>
            <material name="black" />
        </visual>
        
<inertial>
            <origin rpy="-1.57079632679 0 0" xyz="0 0.0625 0" />
            <mass value="1" />
            <inertia ixx="0.00135416666667" ixy="0.0" ixz="0.0" iyy="0.00151041666667" iyz="0.0" izz="0.000416666666667" />
        </inertial>

    </link>
    <joint name="EEFjoint" type="fixed">
        <parent link="link6" />
        <child link="EEFlink" />
        <origin rpy="-1.57079632679 0 0" xyz="0 0.125 0" />
    </joint>
    <!-- 7th EEF Link -->
    <link name="EEFlink">
        <collision>
            <origin rpy="0 0 0" xyz="0 0 0.015" />
            <geometry>
                <box size="0.05 0.05 0.03" />
            </geometry>
        </collision>
        <visual>
            <origin rpy="0 0 0" xyz="0 0 0.015" />
            <geometry>
                <box size="0.05 0.05 0.03" />
            </geometry>
            <material name="orange" />
        </visual>
        
<inertial>
            <origin rpy="0 0 0" xyz="0 0 0.015" />
            <mass value="1" />
            <inertia ixx="0.000283333333333" ixy="0.0" ixz="0.0" iyy="0.000283333333333" iyz="0.0" izz="0.000416666666667" />
        </inertial>

    </link>
    <joint name="left_gripper_joint" type="revolute">
        <axis xyz="0 1 0" />
        <limit effort="1000.0" lower="-0.548" upper="0.548" velocity="0.5" />
        <origin rpy="0 0 0" xyz="-0.01 0 0.03" />
        <parent link="EEFlink" />
        <child link="left_gripper" />
        <limit effort="30" velocity="1.0" />
        <dynamics damping="0.0" friction="0.0" />
    </joint>
    <link name="left_gripper">
        <visual>
            <origin rpy="0.0 -1.57079632679 1.57079632679" xyz="0 0 0" />
            <geometry>
                <mesh filename="package://urdf_tutorial/meshes/l_finger.dae" />
            </geometry>
        </visual>
        <collision>
            <geometry>
                <mesh filename="package://urdf_tutorial/meshes/l_finger.dae" />
            </geometry>
            <origin rpy="0.0 -1.57079632679 1.57079632679" xyz="0 0 0" />
        </collision>
        
<inertial>
            <mass value="0.05" />
            <inertia ixx="1.0" ixy="0.0" ixz="0.0" iyy="1.0" iyz="0.0" izz="1.0" />
        </inertial>

    </link>
    <transmission name="left_gripper_trans" type="SimpleTransmission">
        <type>transmission_interface/SimpleTransmission</type>
        <actuator name="left_gripper_motor">
            <mechanicalReduction>1</mechanicalReduction>
        </actuator>
        <joint name="left_gripper_joint">
            <hardwareInterface>PositionJointInterface</hardwareInterface>
        </joint>
    </transmission>
    <joint name="right_gripper_joint" type="revolute">
        <axis xyz="0 -1 0" />
        <limit effort="1000.0" lower="-0.548" upper="0.548" velocity="0.5" />
        <origin rpy="0 0 0" xyz="0.01 0 0.03" />
        <parent link="EEFlink" />
        <child link="right_gripper" />
        <limit effort="30" velocity="1.0" />
        <dynamics damping="0.0" friction="0.0" />
    </joint>
    <link name="right_gripper">
        <visual>
            <origin rpy="-3.14159265359 -1.57079632679 1.57079632679" xyz="0 0 0" />
            <geometry>
                <mesh filename="package://urdf_tutorial/meshes/l_finger.dae" />
            </geometry>
        </visual>
        <collision>
            <geometry>
                <mesh filename="package://urdf_tutorial/meshes/l_finger.dae" />
            </geometry>
            <origin rpy="-3.14159265359 -1.57079632679 1.57079632679" xyz="0 0 0" />
        </collision>
        
<inertial>
            <mass value="0.05" />
            <inertia ixx="1.0" ixy="0.0" ixz="0.0" iyy="1.0" iyz="0.0" izz="1.0" />
        </inertial>

    </link>
    <transmission name="right_gripper_trans" type="SimpleTransmission">
        <type>transmission_interface/SimpleTransmission</type>
        <actuator name="right_gripper_motor">
            <mechanicalReduction>1</mechanicalReduction>
        </actuator>
        <joint name="right_gripper_joint">
            <hardwareInterface>PositionJointInterface</hardwareInterface>
        </joint>
    </transmission>
    <transmission name="trans_joint0">
        <type>transmission_interface/SimpleTransmission</type>
        <joint name="joint0">
            <hardwareInterface>hardware_interface/EffortJointInterface</hardwareInterface>
        </joint>
        <actuator name="joint0_motor">
            <hardwareInterface>hardware_interface/EffortJointInterface</hardwareInterface>
            <mechanicalReduction>1</mechanicalReduction>
        </actuator>
    </transmission>
    <transmission name="trans_joint1">
        <type>transmission_interface/SimpleTransmission</type>
        <joint name="joint1">
            <hardwareInterface>hardware_interface/EffortJointInterface</hardwareInterface>
        </joint>
        <actuator name="joint1_motor">
            <hardwareInterface>hardware_interface/EffortJointInterface</hardwareInterface>
            <mechanicalReduction>1</mechanicalReduction>
        </actuator>
    </transmission>
    <transmission name="trans_joint2">
        <type>transmission_interface/SimpleTransmission</type>
        <joint name="joint2">
            <hardwareInterface>hardware_interface/EffortJointInterface</hardwareInterface>
        </joint>
        <actuator name="joint2_motor">
            <hardwareInterface>hardware_interface/EffortJointInterface</hardwareInterface>
            <mechanicalReduction>1</mechanicalReduction>
        </actuator>
    </transmission>
    <transmission name="trans_joint3">
        <type>transmission_interface/SimpleTransmission</type>
        <joint name="joint3">
            <hardwareInterface>hardware_interface/EffortJointInterface</hardwareInterface>
        </joint>
        <actuator name="joint3_motor">
            <hardwareInterface>hardware_interface/EffortJointInterface</hardwareInterface>
            <mechanicalReduction>1</mechanicalReduction>
        </actuator>
    </transmission>
    <transmission name="trans_joint4">
        <type>transmission_interface/SimpleTransmission</type>
        <joint name="joint4">
            <hardwareInterface>hardware_interface/EffortJointInterface</hardwareInterface>
        </joint>
        <actuator name="joint4_motor">
            <hardwareInterface>hardware_interface/EffortJointInterface</hardwareInterface>
            <mechanicalReduction>1</mechanicalReduction>
        </actuator>
    </transmission>
    <transmission name="trans_joint5">
        <type>transmission_interface/SimpleTransmission</type>
        <joint name="joint5">
            <hardwareInterface>hardware_interface/EffortJointInterface</hardwareInterface>
        </joint>
        <actuator name="joint5_motor">
            <hardwareInterface>hardware_interface/EffortJointInterface</hardwareInterface>
            <mechanicalReduction>1</mechanicalReduction>
        </actuator>
    </transmission>
    <transmission name="trans_left_gripper_joint">
        <type>transmission_interface/SimpleTransmission</type>
        <joint name="left_gripper_joint">
            <hardwareInterface>hardware_interface/EffortJointInterface</hardwareInterface>
        </joint>
        <actuator name="left_gripper_joint_motor">
            <hardwareInterface>hardware_interface/EffortJointInterface</hardwareInterface>
            <mechanicalReduction>1</mechanicalReduction>
        </actuator>
    </transmission>
    <transmission name="trans_right_gripper_joint">
        <type>transmission_interface/SimpleTransmission</type>
        <joint name="right_gripper_joint">
            <hardwareInterface>hardware_interface/EffortJointInterface</hardwareInterface>
        </joint>
        <actuator name="right_gripper_joint_motor">
            <hardwareInterface>hardware_interface/EffortJointInterface</hardwareInterface>
            <mechanicalReduction>1</mechanicalReduction>
        </actuator>
    </transmission>
    <gazebo>
        <plugin name="gazebo_ros_control" filename="libgazebo_ros_control.so">
            <robotNamespace>/</robotNamespace>
        </plugin>
    </gazebo>
</robot>

<transmission name="left_gripper_trans" type="SimpleTransmission">
        <type>transmission_interface/SimpleTransmission</type>
        <actuator name="left_gripper_motor">
            <mechanicalReduction>1</mechanicalReduction>
        </actuator>
        <joint name="left_gripper_joint">
            <hardwareInterface>PositionJointInterface</hardwareInterface>
        </joint>
    </transmission>
    <joint name="right_gripper_joint" type="revolute">
        <axis xyz="0 -1 0" />
        <limit effort="1000.0" lower="-0.548" upper="0.548" velocity="0.5" />
        <origin rpy="0 0 0" xyz="0.01 0 0.03" />
        <parent link="EEFlink" />
        <child link="right_gripper" />
        <limit effort="30" velocity="1.0" />
        <dynamics damping="0.0" friction="0.0" />
    </joint>
    <link name="right_gripper">
        <visual>
            <origin rpy="-3.14159265359 -1.57079632679 1.57079632679" xyz="0 0 0" />
            <geometry>
                <mesh filename="package://urdf_tutorial/meshes/l_finger.dae" />
            </geometry>
        </visual>
        <collision>
            <geometry>
                <mesh filename="package://urdf_tutorial/meshes/l_finger.dae" />
            </geometry>
            <origin rpy="-3.14159265359 -1.57079632679 1.57079632679" xyz="0 0 0" />
        </collision>
        <inertial>
            <mass value="0.05" />
            <inertia ixx="1.0" ixy="0.0" ixz="0.0" iyy="1.0" iyz="0.0" izz="1.0" />
        </inertial>
    </link>
    <transmission name="right_gripper_trans" type="SimpleTransmission">
        <type>transmission_interface/SimpleTransmission</type>
        <actuator name="right_gripper_motor">
            <mechanicalReduction>1</mechanicalReduction>
        </actuator>
        <joint name="right_gripper_joint">
            <hardwareInterface>PositionJointInterface</hardwareInterface>
        </joint>
    </transmission>
    <transmission name="trans_joint0">
        <type>transmission_interface/SimpleTransmission</type>
        <joint name="joint0">
            <hardwareInterface>hardware_interface/EffortJointInterface</hardwareInterface>
        </joint>
        <actuator name="joint0_motor">
            <hardwareInterface>hardware_interface/EffortJointInterface</hardwareInterface>
            <mechanicalReduction>1</mechanicalReduction>
        </actuator>
    </transmission>
    <transmission name="trans_joint1">
        <type>transmission_interface/SimpleTransmission</type>
        <joint name="joint1">
            <hardwareInterface>hardware_interface/EffortJointInterface</hardwareInterface>
        </joint>
        <actuator name="joint1_motor">
            <hardwareInterface>hardware_interface/EffortJointInterface</hardwareInterface>
            <mechanicalReduction>1</mechanicalReduction>
        </actuator>
    </transmission>
    <transmission name="trans_joint2">
        <type>transmission_interface/SimpleTransmission</type>
        <joint name="joint2">
            <hardwareInterface>hardware_interface/EffortJointInterface</hardwareInterface>
        </joint>
        <actuator name="joint2_motor">
            <hardwareInterface>hardware_interface/EffortJointInterface</hardwareInterface>
            <mechanicalReduction>1</mechanicalReduction>
        </actuator>
    </transmission>
    <transmission name="trans_joint3">
        <type>transmission_interface/SimpleTransmission</type>
        <joint name="joint3">
            <hardwareInterface>hardware_interface/EffortJointInterface</hardwareInterface>
        </joint>
        <actuator name="joint3_motor">
            <hardwareInterface>hardware_interface/EffortJointInterface</hardwareInterface>
            <mechanicalReduction>1</mechanicalReduction>
        </actuator>
    </transmission>
    <transmission name="trans_joint4">
        <type>transmission_interface/SimpleTransmission</type>
        <joint name="joint4">
            <hardwareInterface>hardware_interface/EffortJointInterface</hardwareInterface>
        </joint>
        <actuator name="joint4_motor">
            <hardwareInterface>hardware_interface/EffortJointInterface</hardwareInterface>
            <mechanicalReduction>1</mechanicalReduction>
        </actuator>
    </transmission>
    <transmission name="trans_joint5">
        <type>transmission_interface/SimpleTransmission</type>
        <joint name="joint5">
            <hardwareInterface>hardware_interface/EffortJointInterface</hardwareInterface>
        </joint>
        <actuator name="joint5_motor">
            <hardwareInterface>hardware_interface/EffortJointInterface</hardwareInterface>
            <mechanicalReduction>1</mechanicalReduction>
        </actuator>
    </transmission>
    <transmission name="trans_left_gripper_joint">
        <type>transmission_interface/SimpleTransmission</type>
        <joint name="left_gripper_joint">
            <hardwareInterface>hardware_interface/EffortJointInterface</hardwareInterface>
        </joint>
        <actuator name="left_gripper_joint_motor">
            <hardwareInterface>hardware_interface/EffortJointInterface</hardwareInterface>
            <mechanicalReduction>1</mechanicalReduction>
        </actuator>
    </transmission>
    <transmission name="trans_right_gripper_joint">
        <type>transmission_interface/SimpleTransmission</type>
        <joint name="right_gripper_joint">
            <hardwareInterface>hardware_interface/EffortJointInterface</hardwareInterface>
        </joint>
        <actuator name="right_gripper_joint_motor">
            <hardwareInterface>hardware_interface/EffortJointInterface</hardwareInterface>
            <mechanicalReduction>1</mechanicalReduction>
        </actuator>
    </transmission>
    <gazebo>
        <plugin name="gazebo_ros_control" filename="libgazebo_ros_control.so">
            <robotNamespace>/</robotNamespace>
        </plugin>
    </gazebo>
</robot>