<?xml version="1.0"?>
<!-- Revolute-Revolute Manipulator -->
<robot name="rrbot" xmlns:xacro="http://www.ros.org/wiki/xacro">
    <!--  pararell setting-->
    <xacro:macro name="gripper" params="parent parent_height prefix LorR reflect LowerLim_roll UpperLim_roll PI">
        <joint name="${prefix}${LorR}_gripper_joint" type="revolute">
            <axis xyz="0 ${reflect} 0"/> 
            <limit lower="${LowerLim_roll}" upper="${UpperLim_roll}" effort="0" velocity="0"/>
            <origin rpy="0 0 ${PI/2}" xyz="0 ${reflect*0.03} ${parent_height}"/>
            <parent link="${prefix}${parent}"/>
            <child link="${prefix}${LorR}_gripper"/>
            <dynamics damping="0.0" friction="0.0"/>
        </joint>

        <link name="${prefix}${LorR}_gripper">
            <visual>
            <origin rpy="${(reflect-1)/2*pi} ${-PI/2} ${-PI/2}" xyz="0 0 0"/>
            <geometry>
                <mesh filename="package://urdf_tutorial/meshes/l_finger.dae"/>
            </geometry>
            </visual>
            <collision>
            <geometry>
                <mesh filename="package://urdf_tutorial/meshes/l_finger.dae"/>
            </geometry>
            <origin rpy="${(reflect-1)/2*pi} ${-PI/2} ${-PI/2}" xyz="0 0 0"/>
            </collision>
            <inertial>
            <mass value="1.0" />
            <inertia ixx="1.0" ixy="0.0" ixz="0.0" iyy="1.0" iyz="0.0" izz="1.0" />
            </inertial>
        </link>

        <transmission name="${prefix}${LorR}_gripper_trans" type="SimpleTransmission">
            <type>transmission_interface/SimpleTransmission</type>
            <actuator name="${prefix}${LorR}_gripper_motor">
            <mechanicalReduction>1</mechanicalReduction>
            </actuator>
            <joint name="${prefix}${LorR}_gripper_joint">
            <hardwareInterface>PositionJointInterface</hardwareInterface>
            </joint>
        </transmission>    
    </xacro:macro>

</robot>